Workbook

Sheet Cover
A1: ASSOCIA BRANCH READINESS — INTEGRATED ASSESSMENT v3.0
A3: One document. Branch answers the question. Assessor marks PC / AC / FB. Output sheets auto-populate.
A5: Branch Name
A6: Assessment Date
A7: Assessor
A8: Source System
A10: CLASSIFICATION CODES
A11: PC | B11: Process Change | C11: TownSq supports this natively. Branch must adapt how they work. | E11: Change Plan sheet
A12: AC | B12: Adoption / Config | C12: TownSq supports this after configuration, data setup, or training. | E12: Onboarding List sheet
A13: FB | B13: Feature Backlog | C13: TownSq cannot support this today. Must be built or put on roadmap. | E13: Product Backlog sheet — assign P0–P3
A14: NA | B14: Not Applicable | C14: Branch does not use this capability. | E14: Excluded from score
A16: HOW TO USE
A17: Branch | B17: Send to branch ops lead 3 days before the discovery session. They type their answers in the yellow Answer column.
A18: Assessor | B18: During the 60-min session, read each answer and mark PC / AC / FB / NA in the Classification column.
A19: Auto | B19: The Change Plan, Onboarding List, and Product Backlog sheets auto-populate as you classify.
A20: FB only | B20: For Feature Backlog rows, also set the FB Priority (P0–P3) in column J.
A21: Output | B21: Review the three output sheets — share Change Plan with ops, Onboarding List with implementation, Backlog with product.

Sheet Assessment
A1: BRANCH ASSESSMENT — One row per dimension. Branch answers → Assessor classifies.
A2: BRANCH: Read the Discovery Question in column G and type your answer in column H (yellow). ASSESSOR: Read the branch's answer and mark column I as PC / AC / FB / NA. For FB items, also set FB Priority in column J. Output sheets auto-populate as you classify.
A3: ← READ ONLY — Do not edit columns A–F or K | H3: BRANCH FILLS THIS | I3: SME fills once — one-time exercise | L3: ASSESSOR NOTES
A4: Dom # | B4: Domain | C4: Cap # | D4: Capability | E4: Dimension | F4: Priority | G4: Discovery Question — what to ask the branch | H4: Branch Answer — describe your current process | I4: TownSq Capability — what TownSq supports today | J4: Classification PC / AC / FB / NA | K4: FB Priority (P0–P3 if FB) | L4: Assessor Notes | M4: AC# | N4: FB# | O4: PC# | P4: QID — Dom.Cap.Seq | Q4: UID — permanent key
A5: 1 | B5: Platform Foundation | C5: 1.1 | D5: General System Access | E5: Multi-system navigation | F5: P0 | G5: How many different systems does your branch log into daily? List them ALL by name. | I5: After config — TownSq Business (back-office) and TownSq Community (homeowner portal) are separate logins; WorkPoints+ is the accounting core. Managers must navigate two or three interfaces daily. ~ verify current SSO roadmap | M5: =IF($J5="AC",COUNTIF($J$5:$J5,"AC"),"") | N5: =IF($J5="FB",COUNTIF($J$5:$J5,"FB"),"") | O5: =IF($J5="PC",COUNTIF($J$5:$J5,"PC"),"") | P5: 1.1.1 | Q5: Q0001
A6: 1 | B6: Platform Foundation | C6: 1.1 | D6: General System Access | E6: User account management | F6: P0 | G6: Who manages user account creation, modification and removal today? What is the process when a new employee starts? | I6: After config — User accounts created and managed in TownSq admin console; new-user setup requires admin role. Process differs from legacy systems. ✓ | M6: =IF($J6="AC",COUNTIF($J$5:$J6,"AC"),"") | N6: =IF($J6="FB",COUNTIF($J$5:$J6,"FB"),"") | O6: =IF($J6="PC",COUNTIF($J$5:$J6,"PC"),"") | P6: 1.1.2 | Q6: Q0002
A7: 1 | B7: Platform Foundation | C7: 1.1 | D7: General System Access | E7: Password reset / access mgmt | F7: P0 | G7: What is the step-by-step process when a user is locked out or needs a password reset? | I7: Native — Standard email-based password reset and account recovery; no admin intervention needed for most resets. ✓ | M7: =IF($J7="AC",COUNTIF($J$5:$J7,"AC"),"") | N7: =IF($J7="FB",COUNTIF($J$5:$J7,"FB"),"") | O7: =IF($J7="PC",COUNTIF($J$5:$J7,"PC"),"") | P7: 1.1.3 | Q7: Q0003
A8: 1 | B8: Platform Foundation | C8: 1.1 | D8: General System Access | E8: Issue submission process | F8: P1 | G8: When you find a system bug or need to report a technical problem, what do you do? Who do you contact and how? | I8: After config — Support tickets submitted via TownSq Help Center portal or Associa internal ticketing; process needs to be configured and communicated to branches. ~ | M8: =IF($J8="AC",COUNTIF($J$5:$J8,"AC"),"") | N8: =IF($J8="FB",COUNTIF($J$5:$J8,"FB"),"") | O8: =IF($J8="PC",COUNTIF($J$5:$J8,"PC"),"") | P8: 1.1.4 | Q8: Q0004
A9: 1 | B9: Platform Foundation | C9: 1.2 | D9: User Security / Permissions | E9: Role-based access control | F9: P0 | G9: Who is responsible for managing user security and permissions? Can you restrict what different roles can see or do? | I9: After config — TownSq Business supports role-based permissions (Manager, Admin, Read-Only, Accounting, etc.). Roles assigned per user; granularity varies by module. ✓ | M9: =IF($J9="AC",COUNTIF($J$5:$J9,"AC"),"") | N9: =IF($J9="FB",COUNTIF($J$5:$J9,"FB"),"") | O9: =IF($J9="PC",COUNTIF($J$5:$J9,"PC"),"") | P9: 1.2.1 | Q9: Q0005
A10: 1 | B10: Platform Foundation | C10: 1.2 | D10: User Security / Permissions | E10: Board member access | F10: P0 | G10: Do any board members have direct login access to your systems today? If yes, what can they see or do? | I10: After config — Board members can be granted TownSq Community access to view financials, documents, and announcements. Access scoped to their association only. ✓ | M10: =IF($J10="AC",COUNTIF($J$5:$J10,"AC"),"") | N10: =IF($J10="FB",COUNTIF($J$5:$J10,"FB"),"") | O10: =IF($J10="PC",COUNTIF($J$5:$J10,"PC"),"") | P10: 1.2.2 | Q10: Q0006
A11: 1 | B11: Platform Foundation | C11: 1.2 | D11: User Security / Permissions | E11: Attorney / external access | F11: P1 | G11: Do any affiliated groups — attorneys, collections agencies — have direct access to your systems to manage delinquencies? | I11: Partial — External users (attorneys) can be given read-only Community access but there is no dedicated attorney/legal portal or collections-agency role. ! verify with TownSq product | M11: =IF($J11="AC",COUNTIF($J$5:$J11,"AC"),"") | N11: =IF($J11="FB",COUNTIF($J$5:$J11,"FB"),"") | O11: =IF($J11="PC",COUNTIF($J$5:$J11,"PC"),"") | P11: 1.2.3 | Q11: Q0007
A12: 1 | B12: Platform Foundation | C12: 1.2 | D12: User Security / Permissions | E12: LOA / temporary access mgmt | F12: P2 | G12: Do you have a policy for user access when someone is on extended leave? Describe what happens to their access. | I12: Not supported — No formal LOA workflow; disabling or restricting a user during leave requires manual admin action with no automated reinstatement. ~ | M12: =IF($J12="AC",COUNTIF($J$5:$J12,"AC"),"") | N12: =IF($J12="FB",COUNTIF($J$5:$J12,"FB"),"") | O12: =IF($J12="PC",COUNTIF($J$5:$J12,"PC"),"") | P12: 1.2.4 | Q12: Q0008
A13: 1 | B13: Platform Foundation | C13: 1.3 | D13: Data Management / Master Data | E13: Association record structure | F13: P0 | G13: Are your association IDs consistent (all letters, all numbers, or a mix)? Provide an example. How are they assigned? | I13: After config — Association records structured with a unique ID, legal name, unit count, management contract details. ID format must be standardised before import. ✓ | M13: =IF($J13="AC",COUNTIF($J$5:$J13,"AC"),"") | N13: =IF($J13="FB",COUNTIF($J$5:$J13,"FB"),"") | O13: =IF($J13="PC",COUNTIF($J$5:$J13,"PC"),"") | P13: 1.3.1 | Q13: Q0009
A14: 1 | B14: Platform Foundation | C14: 1.3 | D14: Data Management / Master Data | E14: Unit / lot data completeness | F14: P0 | G14: Do you have a complete list showing the number of units in each association? How current and reliable is that data? | I14: After config — Unit/lot records imported via data migration template; completeness of incoming data drives accuracy. Post-import validation step required. ✓ | M14: =IF($J14="AC",COUNTIF($J$5:$J14,"AC"),"") | N14: =IF($J14="FB",COUNTIF($J$5:$J14,"FB"),"") | O14: =IF($J14="PC",COUNTIF($J$5:$J14,"PC"),"") | P14: 1.3.2 | Q14: Q0010
A15: 1 | B15: Platform Foundation | C15: 1.3 | D15: Data Management / Master Data | E15: Tax ID / legal entity data | F15: P0 | G15: Can you provide a list of Tax IDs for all associations? Are associations listed by common name or legal name? | I15: After config — Tax ID field exists on the association record. Must be populated as part of onboarding; not auto-populated from any external source. ✓ | M15: =IF($J15="AC",COUNTIF($J$5:$J15,"AC"),"") | N15: =IF($J15="FB",COUNTIF($J$5:$J15,"FB"),"") | O15: =IF($J15="PC",COUNTIF($J$5:$J15,"PC"),"") | P15: 1.3.3 | Q15: Q0011
A16: 1 | B16: Platform Foundation | C16: 1.3 | D16: Data Management / Master Data | E16: Transition-in / out process | F16: P0 | G16: Walk through your step-by-step process for setting up a new client when they transition in. Who is involved and how long does it take? | I16: After config — No automated transition-in wizard; new association setup is a multi-step manual process (COA, bank accounts, owner import, billing setup). Guided by implementation checklist. ~ | M16: =IF($J16="AC",COUNTIF($J$5:$J16,"AC"),"") | N16: =IF($J16="FB",COUNTIF($J$5:$J16,"FB"),"") | O16: =IF($J16="PC",COUNTIF($J$5:$J16,"PC"),"") | P16: 1.3.4 | Q16: Q0012
... A92: 5 | B92: Operations & Tasks | C92: 5.6 | D92: Board Packets | E92: Digital distribution to board | F92: P1 | G92: How are packets delivered to board members today — email, portal, physical binder, or a combination? How far in advance? | I92: After config — Board packets distributed digitally to board members via TownSq portal or email. Board members notified on publication. ✓ | M92: =IF($J92="AC",COUNTIF($J$5:$J92,"AC"),"") | N92: =IF($J92="FB",COUNTIF($J$5:$J92,"FB"),"") | O92: =IF($J92="PC",COUNTIF($J$5:$J92,"PC"),"") | P92: 5.6.3 | Q92: Q0088
A93: 6 | B93: Financial Operations | C93: 6.1 | D93: Accounts Payable | E93: Invoice intake & routing | F93: P0 | G93: Walk through your AP process step by step — from invoice receipt to payment. Who touches it at each stage? | I93: After config — AP invoice entry and routing native in TownSq Business (WorkPoints+). Invoice workflow requires GL coding, association assignment, and approver configuration. ✓ | O93: =IF($J93="PC",COUNTIF($J$5:$J93,"PC"),"") | P93: 6.1.1 | Q93: Q0089
A94: 6 | B94: Financial Operations | C94: 6.1 | D94: Accounts Payable | E94: Approval / hold / reject workflow | F94: P0 | G94: Do you have dollar limits that require Board Member or Branch Executive approval before paying an invoice? What are the thresholds and who approves? | I94: After config — Dollar-threshold approval rules configurable in TownSq AP module. Board-approval routing and branch-exec approval rules set during onboarding. ✓ | O94: =IF($J94="PC",COUNTIF($J$5:$J94,"PC"),"") | P94: 6.1.2 | Q94: Q0090
A95: 6 | B95: Financial Operations | C95: 6.1 | D95: Accounts Payable | E95: ACH payment processing | F95: P0 | G95: Do you pay any vendors by ACH? If yes, how do you set up an ACH vendor and how are payments initiated? | I95: After config — ACH vendor payments supported in TownSq. Vendor must have ACH banking details on file; payment runs initiated from AP module. ✓ | O95: =IF($J95="PC",COUNTIF($J$5:$J95,"PC"),"") | P95: 6.1.3 | Q95: Q0091
A96: 6 | B96: Financial Operations | C96: 6.1 | D96: Accounts Payable | E96: Cash-poor / priority handling | F96: P1 | G96: If there is not enough money in an association's bank account to pay a vendor, what happens? Who decides what gets paid and in what order? | I96: Partial — No automated cash-poor / priority queue; assessor or manager manually reviews and holds or prioritises invoices in TownSq when funds are limited. ~ | O96: =IF($J96="PC",COUNTIF($J$5:$J96,"PC"),"") | P96: 6.1.4 | Q96: Q0092
A97: 6 | B97: Financial Operations | C97: 6.1 | D97: Accounts Payable | E97: Invoice history & notes | F97: P1 | G97: How do you view the payment history for a vendor or a specific invoice? Can you add notes or comments to an invoice record? | I97: Native — Full AP invoice history accessible by vendor, association, or date range in TownSq Business. Notes and attachments included. ✓ | O97: =IF($J97="PC",COUNTIF($J$5:$J97,"PC"),"") | P97: 6.1.5 | Q97: Q0093
A98: 6 | B98: Financial Operations | C98: 6.1 | D98: Accounts Payable | E98: Supporting document mgmt | F98: P1 | G98: How are supporting documents (contracts, POs, photos of work) attached to an invoice before it goes through approval? | I98: After config — Supporting documents (contracts, photos of work, purchase orders) attached to invoice records in TownSq before approval routing. ✓ | O98: =IF($J98="PC",COUNTIF($J$5:$J98,"PC"),"") | P98: 6.1.6 | Q98: Q0094
A99: 6 | B99: Financial Operations | C99: 6.1 | D99: Accounts Payable | E99: Duplicate Invoice Control | F99: P0 | G99: How do you detect and prevent duplicate vendor invoices across all entry channels before payment is released? | M99: =IF($J99="AC",COUNTIF($J$5:$J99,"AC"),"") | N99: =IF($J99="FB",COUNTIF($J$5:$J99,"FB"),"") | O99: =IF($J99="PC",COUNTIF($J$5:$J99,"PC"),"") | P99: 6.1.7 | Q99: Q0095
A100: 6 | B100: Financial Operations | C100: 6.1 | D100: Accounts Payable | E100: Vendor Mgmt | F100: P0 | G100: Who owns vendor master maintenance, and how are new vendor records, address changes, and bank detail changes validated before use? | M100: =IF($J100="AC",COUNTIF($J$5:$J100,"AC"),"") | N100: =IF($J100="FB",COUNTIF($J$5:$J100,"FB"),"") | O100: =IF($J100="PC",COUNTIF($J$5:$J100,"PC"),"") | P100: 6.1.8 | Q100: Q0096
A101: 6 | B101: Financial Operations | C101: 6.1 | D101: Accounts Payable | E101: Recurring Charges / Coding Defaults | F101: P0 | G101: Are recurring vendor charges pre-coded from templates/rules, and how are GL/property/class codes populated for new bills? | M101: =IF($J101="AC",COUNTIF($J$5:$J101,"AC"),"") | N101: =IF($J101="FB",COUNTIF($J$5:$J101,"FB"),"") | O101: =IF($J101="PC",COUNTIF($J$5:$J101,"PC"),"") | P101: 6.1.9 | Q101: Q0097
A102: 6 | B102: Financial Operations | C102: 6.1 | D102: Accounts Payable | E102: Contract Matching | F102: P0 | G102: Do you require purchase orders, contracts, or work-order references matched to invoices before approval? Where is that link maintained? | M102: =IF($J102="AC",COUNTIF($J$5:$J102,"AC"),"") | N102: =IF($J102="FB",COUNTIF($J$5:$J102,"FB"),"") | O102: =IF($J102="PC",COUNTIF($J$5:$J102,"PC"),"") | P102: 6.1.10 | Q102: Q0098
A103: 6 | B103: Financial Operations | C103: 6.1 | D103: Accounts Payable | E103: Fraud Controls | F103: P0 | G103: What controls/checks happen between the AP system, the bank, and fraud mitigation measures (e.g., Positive Pay) before money leaves the account? | M103: =IF($J103="AC",COUNTIF($J$5:$J103,"AC"),"") | N103: =IF($J103="FB",COUNTIF($J$5:$J103,"FB"),"") | O103: =IF($J103="PC",COUNTIF($J$5:$J103,"PC"),"") | P103: 6.1.11 | Q103: Q0099
A104: 6 | B104: Financial Operations | C104: 6.1 | D104: Accounts Payable | E104: Exception Handling | F104: P1 | G104: How are voided, stopped, or rejected AP payments traced to the original invoice and reflected in the GL & vendor history? | M104: =IF($J104="AC",COUNTIF($J$5:$J104,"AC"),"") | N104: =IF($J104="FB",COUNTIF($J$5:$J104,"FB"),"") | O104: =IF($J104="PC",COUNTIF($J$5:$J104,"PC"),"") | P104: 6.1.12 | Q104: Q0100
A105: 6 | B105: Financial Operations | C105: 6.1 | D105: Accounts Payable | E105: AP Visibility & Liability Aging | F105: P1 | G105: How do you review AP aging or open liabilities by association, vendor, or approver across the portfolio? | M105: =IF($J105="AC",COUNTIF($J$5:$J105,"AC"),"") | N105: =IF($J105="FB",COUNTIF($J$5:$J105,"FB"),"") | O105: =IF($J105="PC",COUNTIF($J$5:$J105,"PC"),"") | P105: 6.1.13 | Q105: Q0101
A106: 6 | B106: Financial Operations | C106: 6.1 | D106: Accounts Payable | E106: Systems Involved | F106: P0 | G106: Which systems receive AP invoice data after posting (e.g., reporting, document storage, ticketing)—is that sync automated or manual? | M106: =IF($J106="AC",COUNTIF($J$5:$J106,"AC"),"") | N106: =IF($J106="FB",COUNTIF($J$5:$J106,"FB"),"") | O106: =IF($J106="PC",COUNTIF($J$5:$J106,"PC"),"") | P106: 6.1.14 | Q106: Q0102
A107: 6 | B107: Financial Operations | C107: 6.1 | D107: Accounts Payable | E107: Fraud Controls | F107: P0 | G107: What controls are in place to verify the authenticity of vendor invoices and protect against business email compromise/phishing? | M107: =IF($J107="AC",COUNTIF($J$5:$J107,"AC"),"") | N107: =IF($J107="FB",COUNTIF($J$5:$J107,"FB"),"") | O107: =IF($J107="PC",COUNTIF($J$5:$J107,"PC"),"") | P107: 6.1.15 | Q107: Q0103
A108: 6 | B108: Financial Operations | C108: 6.1 | D108: Accounts Payable | E108: Backup Mgmt | F108: P3 | G108: In case of outage/ransomware, how quickly can AP processing resume, and are vendor records backed up offsite? | M108: =IF($J108="AC",COUNTIF($J$5:$J108,"AC"),"") | N108: =IF($J108="FB",COUNTIF($J$5:$J108,"FB"),"") | O108: =IF($J108="PC",COUNTIF($J$5:$J108,"PC"),"") | P108: 6.1.16 | Q108: Q0104
A109: 6 | B109: Financial Operations | C109: 6.1 | D109: Accounts Payable | E109: Regulatory & Compliance Updates | F109: P1 | G109: How does your AP system stay updated for 1099 reporting, IRS/state requirements, or other regulatory changes affecting vendor payments? | M109: =IF($J109="AC",COUNTIF($J$5:$J109,"AC"),"") | N109: =IF($J109="FB",COUNTIF($J$5:$J109,"FB"),"") | O109: =IF($J109="PC",COUNTIF($J$5:$J109,"PC"),"") | P109: 6.1.17 | Q109: Q0105
A110: 6 | B110: Financial Operations | C110: 6.1 | D110: Accounts Payable | E110: Systems Involved | F110: P0 | G110: Are paper invoices still received and, if so, what is the process for digitizing them and using them in existing systems? | M110: =IF($J110="AC",COUNTIF($J$5:$J110,"AC"),"") | N110: =IF($J110="FB",COUNTIF($J$5:$J110,"FB"),"") | O110: =IF($J110="PC",COUNTIF($J$5:$J110,"PC"),"") | P110: 6.1.18 | Q110: Q0106
... A121: 6 | B121: Financial Operations | C121: 6.1 | D121: Accounts Payable | E121: Fraud Controls | F121: P0 | G121: Have you detected or prevented vendor fraud attempts involving multiple HOAs, and how was this identified? | M121: =IF($J121="AC",COUNTIF($J$5:$J121,"AC"),"") | N121: =IF($J121="FB",COUNTIF($J$5:$J121,"FB"),"") | O121: =IF($J121="PC",COUNTIF($J$5:$J121,"PC"),"") | P121: 6.1.29 | Q121: Q0117
A122: 6 | B122: Financial Operations | C122: 6.2 | D122: Accounts Receivable | E122: Lockbox payment processing | F122: P0 | G122: Do you use lockbox processing for homeowner assessment payments? Which bank? What percentage of homeowners pay through the lockbox? | I122: After config — Lockbox payment file import supported in TownSq AR module. Bank sends file; TownSq processes and posts payments. Bank and file format must be configured. ✓ | O122: =IF($J122="PC",COUNTIF($J$5:$J122,"PC"),"") | P122: 6.2.1 | Q122: Q0118
A123: 6 | B123: Financial Operations | C123: 6.2 | D123: Accounts Receivable | E123: ACH / direct debit enrollment | F123: P0 | G123: Does your branch process direct debit (ACH pull) payments from owners? What day of the month are they pulled, and how do owners enroll? Does some one does it for you already or do we need to set it up in TSQB. | I123: There are two types of ACH payment models. One is homeowner-initiated payments through the portal using external providers, and the other is branch-initiated direct debit, where the branch collects bank information and executes a batch process to pull funds from homeowner accounts on a scheduled basis. This question is intended to determine whether the branch uses internal direct debit processing or relies on third-party providers. | O123: =IF($J123="PC",COUNTIF($J$5:$J123,"PC"),"") | P123: 6.2.2 | Q123: Q0119
A124: 6 | B124: Financial Operations | C124: 6.2 | D124: Accounts Receivable | E124: Special assessment processing | F124: P0 | G124: Do any associations currently have special assessments? Describe how those payments are collected, recorded, and tracked separately from regular dues. What method do you use - Lump sum, multi year payments (late fee schedule) | I124: Special assessments can be handled in multiple ways depending on association requirements. They may be collected as a one-time lump sum, structured as multi-year installment plans, or tracked in separate ledgers distinct from regular dues. In some cases, special assessments may also follow different delinquency rules. The purpose of this question is to understand the specific approach used so it can be properly configured during implementation. | O124: =IF($J124="PC",COUNTIF($J$5:$J124,"PC"),"") | P124: 6.2.3 | Q124: Q0120
A125: 6 | B125: Financial Operations | C125: 6.2 | D125: Accounts Receivable | E125: Payment exceptions handling | F125: P1 | G125: On average, how many lockbox exceptions does your branch handle each day? What types of exceptions occur most often and how are they resolved? | I125: After config — Lockbox exceptions handled manually in TownSq; exception report generated after each file load. Resolution process defined in onboarding. ✓ | O125: =IF($J125="PC",COUNTIF($J$5:$J125,"PC"),"") | P125: 6.2.4 | Q125: Q0121
...

Sheet Change Plan (PC)
A1: CHANGE PLAN (PC)
A3: Process Change items — TownSq supports these natively but the branch currently works differently. Column 'TownSq supports today' shows exactly what TownSq does. Fill in the required workflow change, assign an Owner, and set a Target Date.
A4: Row# | B4: Domain | C4: Capability | D4: Dimension | E4: Discovery Question | F4: Branch Answer | G4: TownSq supports today | H4: Required change in TownSq | I4: Owner | J4: Target Date
A5: =IFERROR(MATCH(1,Assessment!$O:$O,0),"") | B5: =IF($A5="","",INDEX(Assessment!$B:$B,$A5)) | C5: =IF($A5="","",INDEX(Assessment!$D:$D,$A5)) | D5: =IF($A5="","",INDEX(Assessment!$E:$E,$A5)) | E5: =IF($A5="","",INDEX(Assessment!$G:$G,$A5)) | F5: =IF($A5="","",INDEX(Assessment!$H:$H,$A5)) | G5: =IF($A5="","",INDEX(Assessment!$I:$I,$A5))
A6: =IFERROR(MATCH(2,Assessment!$O:$O,0),"") | B6: =IF($A6="","",INDEX(Assessment!$B:$B,$A6)) | C6: =IF($A6="","",INDEX(Assessment!$D:$D,$A6)) | D6: =IF($A6="","",INDEX(Assessment!$E:$E,$A6)) | E6: =IF($A6="","",INDEX(Assessment!$G:$G,$A6)) | F6: =IF($A6="","",INDEX(Assessment!$H:$H,$A6)) | G6: =IF($A6="","",INDEX(Assessment!$I:$I,$A6))
A7: =IFERROR(MATCH(3,Assessment!$O:$O,0),"") | B7: =IF($A7="","",INDEX(Assessment!$B:$B,$A7)) | C7: =IF($A7="","",INDEX(Assessment!$D:$D,$A7)) | D7: =IF($A7="","",INDEX(Assessment!$E:$E,$A7)) | E7: =IF($A7="","",INDEX(Assessment!$G:$G,$A7)) | F7: =IF($A7="","",INDEX(Assessment!$H:$H,$A7)) | G7: =IF($A7="","",INDEX(Assessment!$I:$I,$A7))
A8: =IFERROR(MATCH(4,Assessment!$O:$O,0),"") | B8: =IF($A8="","",INDEX(Assessment!$B:$B,$A8)) | C8: =IF($A8="","",INDEX(Assessment!$D:$D,$A8)) | D8: =IF($A8="","",INDEX(Assessment!$E:$E,$A8)) | E8: =IF($A8="","",INDEX(Assessment!$G:$G,$A8)) | F8: =IF($A8="","",INDEX(Assessment!$H:$H,$A8)) | G8: =IF($A8="","",INDEX(Assessment!$I:$I,$A8))
A9: =IFERROR(MATCH(5,Assessment!$O:$O,0),"") | B9: =IF($A9="","",INDEX(Assessment!$B:$B,$A9)) | C9: =IF($A9="","",INDEX(Assessment!$D:$D,$A9)) | D9: =IF($A9="","",INDEX(Assessment!$E:$E,$A9)) | E9: =IF($A9="","",INDEX(Assessment!$G:$G,$A9)) | F9: =IF($A9="","",INDEX(Assessment!$H:$H,$A9)) | G9: =IF($A9="","",INDEX(Assessment!$I:$I,$A9))
A10: =IFERROR(MATCH(6,Assessment!$O:$O,0),"") | B10: =IF($A10="","",INDEX(Assessment!$B:$B,$A10)) | C10: =IF($A10="","",INDEX(Assessment!$D:$D,$A10)) | D10: =IF($A10="","",INDEX(Assessment!$E:$E,$A10)) | E10: =IF($A10="","",INDEX(Assessment!$G:$G,$A10)) | F10: =IF($A10="","",INDEX(Assessment!$H:$H,$A10)) | G10: =IF($A10="","",INDEX(Assessment!$I:$I,$A10))
A11: =IFERROR(MATCH(7,Assessment!$O:$O,0),"") | B11: =IF($A11="","",INDEX(Assessment!$B:$B,$A11)) | C11: =IF($A11="","",INDEX(Assessment!$D:$D,$A11)) | D11: =IF($A11="","",INDEX(Assessment!$E:$E,$A11)) | E11: =IF($A11="","",INDEX(Assessment!$G:$G,$A11)) | F11: =IF($A11="","",INDEX(Assessment!$H:$H,$A11)) | G11: =IF($A11="","",INDEX(Assessment!$I:$I,$A11))
A12: =IFERROR(MATCH(8,Assessment!$O:$O,0),"") | B12: =IF($A12="","",INDEX(Assessment!$B:$B,$A12)) | C12: =IF($A12="","",INDEX(Assessment!$D:$D,$A12)) | D12: =IF($A12="","",INDEX(Assessment!$E:$E,$A12)) | E12: =IF($A12="","",INDEX(Assessment!$G:$G,$A12)) | F12: =IF($A12="","",INDEX(Assessment!$H:$H,$A12)) | G12: =IF($A12="","",INDEX(Assessment!$I:$I,$A12))
A13: =IFERROR(MATCH(9,Assessment!$O:$O,0),"") | B13: =IF($A13="","",INDEX(Assessment!$B:$B,$A13)) | C13: =IF($A13="","",INDEX(Assessment!$D:$D,$A13)) | D13: =IF($A13="","",INDEX(Assessment!$E:$E,$A13)) | E13: =IF($A13="","",INDEX(Assessment!$G:$G,$A13)) | F13: =IF($A13="","",INDEX(Assessment!$H:$H,$A13)) | G13: =IF($A13="","",INDEX(Assessment!$I:$I,$A13))
A14: =IFERROR(MATCH(10,Assessment!$O:$O,0),"") | B14: =IF($A14="","",INDEX(Assessment!$B:$B,$A14)) | C14: =IF($A14="","",INDEX(Assessment!$D:$D,$A14)) | D14: =IF($A14="","",INDEX(Assessment!$E:$E,$A14)) | E14: =IF($A14="","",INDEX(Assessment!$G:$G,$A14)) | F14: =IF($A14="","",INDEX(Assessment!$H:$H,$A14)) | G14: =IF($A14="","",INDEX(Assessment!$I:$I,$A14))
A15: =IFERROR(MATCH(11,Assessment!$O:$O,0),"") | B15: =IF($A15="","",INDEX(Assessment!$B:$B,$A15)) | C15: =IF($A15="","",INDEX(Assessment!$D:$D,$A15)) | D15: =IF($A15="","",INDEX(Assessment!$E:$E,$A15)) | E15: =IF($A15="","",INDEX(Assessment!$G:$G,$A15)) | F15: =IF($A15="","",INDEX(Assessment!$H:$H,$A15)) | G15: =IF($A15="","",INDEX(Assessment!$I:$I,$A15))
A16: =IFERROR(MATCH(12,Assessment!$O:$O,0),"") | B16: =IF($A16="","",INDEX(Assessment!$B:$B,$A16)) | C16: =IF($A16="","",INDEX(Assessment!$D:$D,$A16)) | D16: =IF($A16="","",INDEX(Assessment!$E:$E,$A16)) | E16: =IF($A16="","",INDEX(Assessment!$G:$G,$A16)) | F16: =IF($A16="","",INDEX(Assessment!$H:$H,$A16)) | G16: =IF($A16="","",INDEX(Assessment!$I:$I,$A16))
A17: =IFERROR(MATCH(13,Assessment!$O:$O,0),"") | B17: =IF($A17="","",INDEX(Assessment!$B:$B,$A17)) | C17: =IF($A17="","",INDEX(Assessment!$D:$D,$A17)) | D17: =IF($A17="","",INDEX(Assessment!$E:$E,$A17)) | E17: =IF($A17="","",INDEX(Assessment!$G:$G,$A17)) | F17: =IF($A17="","",INDEX(Assessment!$H:$H,$A17)) | G17: =IF($A17="","",INDEX(Assessment!$I:$I,$A17))
A18: =IFERROR(MATCH(14,Assessment!$O:$O,0),"") | B18: =IF($A18="","",INDEX(Assessment!$B:$B,$A18)) | C18: =IF($A18="","",INDEX(Assessment!$D:$D,$A18)) | D18: =IF($A18="","",INDEX(Assessment!$E:$E,$A18)) | E18: =IF($A18="","",INDEX(Assessment!$G:$G,$A18)) | F18: =IF($A18="","",INDEX(Assessment!$H:$H,$A18)) | G18: =IF($A18="","",INDEX(Assessment!$I:$I,$A18))
A19: =IFERROR(MATCH(15,Assessment!$O:$O,0),"") | B19: =IF($A19="","",INDEX(Assessment!$B:$B,$A19)) | C19: =IF($A19="","",INDEX(Assessment!$D:$D,$A19)) | D19: =IF($A19="","",INDEX(Assessment!$E:$E,$A19)) | E19: =IF($A19="","",INDEX(Assessment!$G:$G,$A19)) | F19: =IF($A19="","",INDEX(Assessment!$H:$H,$A19)) | G19: =IF($A19="","",INDEX(Assessment!$I:$I,$A19))
A20: =IFERROR(MATCH(16,Assessment!$O:$O,0),"") | B20: =IF($A20="","",INDEX(Assessment!$B:$B,$A20)) | C20: =IF($A20="","",INDEX(Assessment!$D:$D,$A20)) | D20: =IF($A20="","",INDEX(Assessment!$E:$E,$A20)) | E20: =IF($A20="","",INDEX(Assessment!$G:$G,$A20)) | F20: =IF($A20="","",INDEX(Assessment!$H:$H,$A20)) | G20: =IF($A20="","",INDEX(Assessment!$I:$I,$A20))
A21: =IFERROR(MATCH(17,Assessment!$O:$O,0),"") | B21: =IF($A21="","",INDEX(Assessment!$B:$B,$A21)) | C21: =IF($A21="","",INDEX(Assessment!$D:$D,$A21)) | D21: =IF($A21="","",INDEX(Assessment!$E:$E,$A21)) | E21: =IF($A21="","",INDEX(Assessment!$G:$G,$A21)) | F21: =IF($A21="","",INDEX(Assessment!$H:$H,$A21)) | G21: =IF($A21="","",INDEX(Assessment!$I:$I,$A21))
A22: =IFERROR(MATCH(18,Assessment!$O:$O,0),"") | B22: =IF($A22="","",INDEX(Assessment!$B:$B,$A22)) | C22: =IF($A22="","",INDEX(Assessment!$D:$D,$A22)) | D22: =IF($A22="","",INDEX(Assessment!$E:$E,$A22)) | E22: =IF($A22="","",INDEX(Assessment!$G:$G,$A22)) | F22: =IF($A22="","",INDEX(Assessment!$H:$H,$A22)) | G22: =IF($A22="","",INDEX(Assessment!$I:$I,$A22))
A23: =IFERROR(MATCH(19,Assessment!$O:$O,0),"") | B23: =IF($A23="","",INDEX(Assessment!$B:$B,$A23)) | C23: =IF($A23="","",INDEX(Assessment!$D:$D,$A23)) | D23: =IF($A23="","",INDEX(Assessment!$E:$E,$A23)) | E23: =IF($A23="","",INDEX(Assessment!$G:$G,$A23)) | F23: =IF($A23="","",INDEX(Assessment!$H:$H,$A23)) | G23: =IF($A23="","",INDEX(Assessment!$I:$I,$A23))
A24: =IFERROR(MATCH(20,Assessment!$O:$O,0),"") | B24: =IF($A24="","",INDEX(Assessment!$B:$B,$A24)) | C24: =IF($A24="","",INDEX(Assessment!$D:$D,$A24)) | D24: =IF($A24="","",INDEX(Assessment!$E:$E,$A24)) | E24: =IF($A24="","",INDEX(Assessment!$G:$G,$A24)) | F24: =IF($A24="","",INDEX(Assessment!$H:$H,$A24)) | G24: =IF($A24="","",INDEX(Assessment!$I:$I,$A24))
A25: =IFERROR(MATCH(21,Assessment!$O:$O,0),"") | B25: =IF($A25="","",INDEX(Assessment!$B:$B,$A25)) | C25: =IF($A25="","",INDEX(Assessment!$D:$D,$A25)) | D25: =IF($A25="","",INDEX(Assessment!$E:$E,$A25)) | E25: =IF($A25="","",INDEX(Assessment!$G:$G,$A25)) | F25: =IF($A25="","",INDEX(Assessment!$H:$H,$A25)) | G25: =IF($A25="","",INDEX(Assessment!$I:$I,$A25))
A26: =IFERROR(MATCH(22,Assessment!$O:$O,0),"") | B26: =IF($A26="","",INDEX(Assessment!$B:$B,$A26)) | C26: =IF($A26="","",INDEX(Assessment!$D:$D,$A26)) | D26: =IF($A26="","",INDEX(Assessment!$E:$E,$A26)) | E26: =IF($A26="","",INDEX(Assessment!$G:$G,$A26)) | F26: =IF($A26="","",INDEX(Assessment!$H:$H,$A26)) | G26: =IF($A26="","",INDEX(Assessment!$I:$I,$A26))
A27: =IFERROR(MATCH(23,Assessment!$O:$O,0),"") | B27: =IF($A27="","",INDEX(Assessment!$B:$B,$A27)) | C27: =IF($A27="","",INDEX(Assessment!$D:$D,$A27)) | D27: =IF($A27="","",INDEX(Assessment!$E:$E,$A27)) | E27: =IF($A27="","",INDEX(Assessment!$G:$G,$A27)) | F27: =IF($A27="","",INDEX(Assessment!$H:$H,$A27)) | G27: =IF($A27="","",INDEX(Assessment!$I:$I,$A27))
A28: =IFERROR(MATCH(24,Assessment!$O:$O,0),"") | B28: =IF($A28="","",INDEX(Assessment!$B:$B,$A28)) | C28: =IF($A28="","",INDEX(Assessment!$D:$D,$A28)) | D28: =IF($A28="","",INDEX(Assessment!$E:$E,$A28)) | E28: =IF($A28="","",INDEX(Assessment!$G:$G,$A28)) | F28: =IF($A28="","",INDEX(Assessment!$H:$H,$A28)) | G28: =IF($A28="","",INDEX(Assessment!$I:$I,$A28))
A29: =IFERROR(MATCH(25,Assessment!$O:$O,0),"") | B29: =IF($A29="","",INDEX(Assessment!$B:$B,$A29)) | C29: =IF($A29="","",INDEX(Assessment!$D:$D,$A29)) | D29: =IF($A29="","",INDEX(Assessment!$E:$E,$A29)) | E29: =IF($A29="","",INDEX(Assessment!$G:$G,$A29)) | F29: =IF($A29="","",INDEX(Assessment!$H:$H,$A29)) | G29: =IF($A29="","",INDEX(Assessment!$I:$I,$A29))
A30: =IFERROR(MATCH(26,Assessment!$O:$O,0),"") | B30: =IF($A30="","",INDEX(Assessment!$B:$B,$A30)) | C30: =IF($A30="","",INDEX(Assessment!$D:$D,$A30)) | D30: =IF($A30="","",INDEX(Assessment!$E:$E,$A30)) | E30: =IF($A30="","",INDEX(Assessment!$G:$G,$A30)) | F30: =IF($A30="","",INDEX(Assessment!$H:$H,$A30)) | G30: =IF($A30="","",INDEX(Assessment!$I:$I,$A30))
A31: =IFERROR(MATCH(27,Assessment!$O:$O,0),"") | B31: =IF($A31="","",INDEX(Assessment!$B:$B,$A31)) | C31: =IF($A31="","",INDEX(Assessment!$D:$D,$A31)) | D31: =IF($A31="","",INDEX(Assessment!$E:$E,$A31)) | E31: =IF($A31="","",INDEX(Assessment!$G:$G,$A31)) | F31: =IF($A31="","",INDEX(Assessment!$H:$H,$A31)) | G31: =IF($A31="","",INDEX(Assessment!$I:$I,$A31))
A32: =IFERROR(MATCH(28,Assessment!$O:$O,0),"") | B32: =IF($A32="","",INDEX(Assessment!$B:$B,$A32)) | C32: =IF($A32="","",INDEX(Assessment!$D:$D,$A32)) | D32: =IF($A32="","",INDEX(Assessment!$E:$E,$A32)) | E32: =IF($A32="","",INDEX(Assessment!$G:$G,$A32)) | F32: =IF($A32="","",INDEX(Assessment!$H:$H,$A32)) | G32: =IF($A32="","",INDEX(Assessment!$I:$I,$A32))
A33: =IFERROR(MATCH(29,Assessment!$O:$O,0),"") | B33: =IF($A33="","",INDEX(Assessment!$B:$B,$A33)) | C33: =IF($A33="","",INDEX(Assessment!$D:$D,$A33)) | D33: =IF($A33="","",INDEX(Assessment!$E:$E,$A33)) | E33: =IF($A33="","",INDEX(Assessment!$G:$G,$A33)) | F33: =IF($A33="","",INDEX(Assessment!$H:$H,$A33)) | G33: =IF($A33="","",INDEX(Assessment!$I:$I,$A33))
A34: =IFERROR(MATCH(30,Assessment!$O:$O,0),"") | B34: =IF($A34="","",INDEX(Assessment!$B:$B,$A34)) | C34: =IF($A34="","",INDEX(Assessment!$D:$D,$A34)) | D34: =IF($A34="","",INDEX(Assessment!$E:$E,$A34)) | E34: =IF($A34="","",INDEX(Assessment!$G:$G,$A34)) | F34: =IF($A34="","",INDEX(Assessment!$H:$H,$A34)) | G34: =IF($A34="","",INDEX(Assessment!$I:$I,$A34))
A35: =IFERROR(MATCH(31,Assessment!$O:$O,0),"") | B35: =IF($A35="","",INDEX(Assessment!$B:$B,$A35)) | C35: =IF($A35="","",INDEX(Assessment!$D:$D,$A35)) | D35: =IF($A35="","",INDEX(Assessment!$E:$E,$A35)) | E35: =IF($A35="","",INDEX(Assessment!$G:$G,$A35)) | F35: =IF($A35="","",INDEX(Assessment!$H:$H,$A35)) | G35: =IF($A35="","",INDEX(Assessment!$I:$I,$A35))
A36: =IFERROR(MATCH(32,Assessment!$O:$O,0),"") | B36: =IF($A36="","",INDEX(Assessment!$B:$B,$A36)) | C36: =IF($A36="","",INDEX(Assessment!$D:$D,$A36)) | D36: =IF($A36="","",INDEX(Assessment!$E:$E,$A36)) | E36: =IF($A36="","",INDEX(Assessment!$G:$G,$A36)) | F36: =IF($A36="","",INDEX(Assessment!$H:$H,$A36)) | G36: =IF($A36="","",INDEX(Assessment!$I:$I,$A36))
A37: =IFERROR(MATCH(33,Assessment!$O:$O,0),"") | B37: =IF($A37="","",INDEX(Assessment!$B:$B,$A37)) | C37: =IF($A37="","",INDEX(Assessment!$D:$D,$A37)) | D37: =IF($A37="","",INDEX(Assessment!$E:$E,$A37)) | E37: =IF($A37="","",INDEX(Assessment!$G:$G,$A37)) | F37: =IF($A37="","",INDEX(Assessment!$H:$H,$A37)) | G37: =IF($A37="","",INDEX(Assessment!$I:$I,$A37))
A38: =IFERROR(MATCH(34,Assessment!$O:$O,0),"") | B38: =IF($A38="","",INDEX(Assessment!$B:$B,$A38)) | C38: =IF($A38="","",INDEX(Assessment!$D:$D,$A38)) | D38: =IF($A38="","",INDEX(Assessment!$E:$E,$A38)) | E38: =IF($A38="","",INDEX(Assessment!$G:$G,$A38)) | F38: =IF($A38="","",INDEX(Assessment!$H:$H,$A38)) | G38: =IF($A38="","",INDEX(Assessment!$I:$I,$A38))
A39: =IFERROR(MATCH(35,Assessment!$O:$O,0),"") | B39: =IF($A39="","",INDEX(Assessment!$B:$B,$A39)) | C39: =IF($A39="","",INDEX(Assessment!$D:$D,$A39)) | D39: =IF($A39="","",INDEX(Assessment!$E:$E,$A39)) | E39: =IF($A39="","",INDEX(Assessment!$G:$G,$A39)) | F39: =IF($A39="","",INDEX(Assessment!$H:$H,$A39)) | G39: =IF($A39="","",INDEX(Assessment!$I:$I,$A39))
A40: =IFERROR(MATCH(36,Assessment!$O:$O,0),"") | B40: =IF($A40="","",INDEX(Assessment!$B:$B,$A40)) | C40: =IF($A40="","",INDEX(Assessment!$D:$D,$A40)) | D40: =IF($A40="","",INDEX(Assessment!$E:$E,$A40)) | E40: =IF($A40="","",INDEX(Assessment!$G:$G,$A40)) | F40: =IF($A40="","",INDEX(Assessment!$H:$H,$A40)) | G40: =IF($A40="","",INDEX(Assessment!$I:$I,$A40))
A41: =IFERROR(MATCH(37,Assessment!$O:$O,0),"") | B41: =IF($A41="","",INDEX(Assessment!$B:$B,$A41)) | C41: =IF($A41="","",INDEX(Assessment!$D:$D,$A41)) | D41: =IF($A41="","",INDEX(Assessment!$E:$E,$A41)) | E41: =IF($A41="","",INDEX(Assessment!$G:$G,$A41)) | F41: =IF($A41="","",INDEX(Assessment!$H:$H,$A41)) | G41: =IF($A41="","",INDEX(Assessment!$I:$I,$A41))
...

Sheet Onboarding List (AC)
A1: ONBOARDING LIST (AC)
A3: Adoption / Config items — TownSq can do this after setup, configuration, or training. Column 'TownSq supports today' shows what needs to be configured. All items must be resolved before or at go-live.
A4: Row# | B4: Domain | C4: Capability | D4: Dimension | E4: Discovery Question | F4: Branch Answer | G4: TownSq supports today | H4: Setup / Config Needed | I4: Training Required? | J4: Owner | K4: Status
A5: =IFERROR(MATCH(1,Assessment!$M:$M,0),"") | B5: =IF($A5="","",INDEX(Assessment!$B:$B,$A5)) | C5: =IF($A5="","",INDEX(Assessment!$D:$D,$A5)) | D5: =IF($A5="","",INDEX(Assessment!$E:$E,$A5)) | E5: =IF($A5="","",INDEX(Assessment!$G:$G,$A5)) | F5: =IF($A5="","",INDEX(Assessment!$H:$H,$A5)) | G5: =IF($A5="","",INDEX(Assessment!$I:$I,$A5))
A6: =IFERROR(MATCH(2,Assessment!$M:$M,0),"") | B6: =IF($A6="","",INDEX(Assessment!$B:$B,$A6)) | C6: =IF($A6="","",INDEX(Assessment!$D:$D,$A6)) | D6: =IF($A6="","",INDEX(Assessment!$E:$E,$A6)) | E6: =IF($A6="","",INDEX(Assessment!$G:$G,$A6)) | F6: =IF($A6="","",INDEX(Assessment!$H:$H,$A6)) | G6: =IF($A6="","",INDEX(Assessment!$I:$I,$A6))
A7: =IFERROR(MATCH(3,Assessment!$M:$M,0),"") | B7: =IF($A7="","",INDEX(Assessment!$B:$B,$A7)) | C7: =IF($A7="","",INDEX(Assessment!$D:$D,$A7)) | D7: =IF($A7="","",INDEX(Assessment!$E:$E,$A7)) | E7: =IF($A7="","",INDEX(Assessment!$G:$G,$A7)) | F7: =IF($A7="","",INDEX(Assessment!$H:$H,$A7)) | G7: =IF($A7="","",INDEX(Assessment!$I:$I,$A7))
A8: =IFERROR(MATCH(4,Assessment!$M:$M,0),"") | B8: =IF($A8="","",INDEX(Assessment!$B:$B,$A8)) | C8: =IF($A8="","",INDEX(Assessment!$D:$D,$A8)) | D8: =IF($A8="","",INDEX(Assessment!$E:$E,$A8)) | E8: =IF($A8="","",INDEX(Assessment!$G:$G,$A8)) | F8: =IF($A8="","",INDEX(Assessment!$H:$H,$A8)) | G8: =IF($A8="","",INDEX(Assessment!$I:$I,$A8))
A9: =IFERROR(MATCH(5,Assessment!$M:$M,0),"") | B9: =IF($A9="","",INDEX(Assessment!$B:$B,$A9)) | C9: =IF($A9="","",INDEX(Assessment!$D:$D,$A9)) | D9: =IF($A9="","",INDEX(Assessment!$E:$E,$A9)) | E9: =IF($A9="","",INDEX(Assessment!$G:$G,$A9)) | F9: =IF($A9="","",INDEX(Assessment!$H:$H,$A9)) | G9: =IF($A9="","",INDEX(Assessment!$I:$I,$A9))
A10: =IFERROR(MATCH(6,Assessment!$M:$M,0),"") | B10: =IF($A10="","",INDEX(Assessment!$B:$B,$A10)) | C10: =IF($A10="","",INDEX(Assessment!$D:$D,$A10)) | D10: =IF($A10="","",INDEX(Assessment!$E:$E,$A10)) | E10: =IF($A10="","",INDEX(Assessment!$G:$G,$A10)) | F10: =IF($A10="","",INDEX(Assessment!$H:$H,$A10)) | G10: =IF($A10="","",INDEX(Assessment!$I:$I,$A10))
A11: =IFERROR(MATCH(7,Assessment!$M:$M,0),"") | B11: =IF($A11="","",INDEX(Assessment!$B:$B,$A11)) | C11: =IF($A11="","",INDEX(Assessment!$D:$D,$A11)) | D11: =IF($A11="","",INDEX(Assessment!$E:$E,$A11)) | E11: =IF($A11="","",INDEX(Assessment!$G:$G,$A11)) | F11: =IF($A11="","",INDEX(Assessment!$H:$H,$A11)) | G11: =IF($A11="","",INDEX(Assessment!$I:$I,$A11))
A12: =IFERROR(MATCH(8,Assessment!$M:$M,0),"") | B12: =IF($A12="","",INDEX(Assessment!$B:$B,$A12)) | C12: =IF($A12="","",INDEX(Assessment!$D:$D,$A12)) | D12: =IF($A12="","",INDEX(Assessment!$E:$E,$A12)) | E12: =IF($A12="","",INDEX(Assessment!$G:$G,$A12)) | F12: =IF($A12="","",INDEX(Assessment!$H:$H,$A12)) | G12: =IF($A12="","",INDEX(Assessment!$I:$I,$A12))
A13: =IFERROR(MATCH(9,Assessment!$M:$M,0),"") | B13: =IF($A13="","",INDEX(Assessment!$B:$B,$A13)) | C13: =IF($A13="","",INDEX(Assessment!$D:$D,$A13)) | D13: =IF($A13="","",INDEX(Assessment!$E:$E,$A13)) | E13: =IF($A13="","",INDEX(Assessment!$G:$G,$A13)) | F13: =IF($A13="","",INDEX(Assessment!$H:$H,$A13)) | G13: =IF($A13="","",INDEX(Assessment!$I:$I,$A13))
A14: =IFERROR(MATCH(10,Assessment!$M:$M,0),"") | B14: =IF($A14="","",INDEX(Assessment!$B:$B,$A14)) | C14: =IF($A14="","",INDEX(Assessment!$D:$D,$A14)) | D14: =IF($A14="","",INDEX(Assessment!$E:$E,$A14)) | E14: =IF($A14="","",INDEX(Assessment!$G:$G,$A14)) | F14: =IF($A14="","",INDEX(Assessment!$H:$H,$A14)) | G14: =IF($A14="","",INDEX(Assessment!$I:$I,$A14))
A15: =IFERROR(MATCH(11,Assessment!$M:$M,0),"") | B15: =IF($A15="","",INDEX(Assessment!$B:$B,$A15)) | C15: =IF($A15="","",INDEX(Assessment!$D:$D,$A15)) | D15: =IF($A15="","",INDEX(Assessment!$E:$E,$A15)) | E15: =IF($A15="","",INDEX(Assessment!$G:$G,$A15)) | F15: =IF($A15="","",INDEX(Assessment!$H:$H,$A15)) | G15: =IF($A15="","",INDEX(Assessment!$I:$I,$A15))
A16: =IFERROR(MATCH(12,Assessment!$M:$M,0),"") | B16: =IF($A16="","",INDEX(Assessment!$B:$B,$A16)) | C16: =IF($A16="","",INDEX(Assessment!$D:$D,$A16)) | D16: =IF($A16="","",INDEX(Assessment!$E:$E,$A16)) | E16: =IF($A16="","",INDEX(Assessment!$G:$G,$A16)) | F16: =IF($A16="","",INDEX(Assessment!$H:$H,$A16)) | G16: =IF($A16="","",INDEX(Assessment!$I:$I,$A16))
A17: =IFERROR(MATCH(13,Assessment!$M:$M,0),"") | B17: =IF($A17="","",INDEX(Assessment!$B:$B,$A17)) | C17: =IF($A17="","",INDEX(Assessment!$D:$D,$A17)) | D17: =IF($A17="","",INDEX(Assessment!$E:$E,$A17)) | E17: =IF($A17="","",INDEX(Assessment!$G:$G,$A17)) | F17: =IF($A17="","",INDEX(Assessment!$H:$H,$A17)) | G17: =IF($A17="","",INDEX(Assessment!$I:$I,$A17))
A18: =IFERROR(MATCH(14,Assessment!$M:$M,0),"") | B18: =IF($A18="","",INDEX(Assessment!$B:$B,$A18)) | C18: =IF($A18="","",INDEX(Assessment!$D:$D,$A18)) | D18: =IF($A18="","",INDEX(Assessment!$E:$E,$A18)) | E18: =IF($A18="","",INDEX(Assessment!$G:$G,$A18)) | F18: =IF($A18="","",INDEX(Assessment!$H:$H,$A18)) | G18: =IF($A18="","",INDEX(Assessment!$I:$I,$A18))
A19: =IFERROR(MATCH(15,Assessment!$M:$M,0),"") | B19: =IF($A19="","",INDEX(Assessment!$B:$B,$A19)) | C19: =IF($A19="","",INDEX(Assessment!$D:$D,$A19)) | D19: =IF($A19="","",INDEX(Assessment!$E:$E,$A19)) | E19: =IF($A19="","",INDEX(Assessment!$G:$G,$A19)) | F19: =IF($A19="","",INDEX(Assessment!$H:$H,$A19)) | G19: =IF($A19="","",INDEX(Assessment!$I:$I,$A19))
A20: =IFERROR(MATCH(16,Assessment!$M:$M,0),"") | B20: =IF($A20="","",INDEX(Assessment!$B:$B,$A20)) | C20: =IF($A20="","",INDEX(Assessment!$D:$D,$A20)) | D20: =IF($A20="","",INDEX(Assessment!$E:$E,$A20)) | E20: =IF($A20="","",INDEX(Assessment!$G:$G,$A20)) | F20: =IF($A20="","",INDEX(Assessment!$H:$H,$A20)) | G20: =IF($A20="","",INDEX(Assessment!$I:$I,$A20))
A21: =IFERROR(MATCH(17,Assessment!$M:$M,0),"") | B21: =IF($A21="","",INDEX(Assessment!$B:$B,$A21)) | C21: =IF($A21="","",INDEX(Assessment!$D:$D,$A21)) | D21: =IF($A21="","",INDEX(Assessment!$E:$E,$A21)) | E21: =IF($A21="","",INDEX(Assessment!$G:$G,$A21)) | F21: =IF($A21="","",INDEX(Assessment!$H:$H,$A21)) | G21: =IF($A21="","",INDEX(Assessment!$I:$I,$A21))
A22: =IFERROR(MATCH(18,Assessment!$M:$M,0),"") | B22: =IF($A22="","",INDEX(Assessment!$B:$B,$A22)) | C22: =IF($A22="","",INDEX(Assessment!$D:$D,$A22)) | D22: =IF($A22="","",INDEX(Assessment!$E:$E,$A22)) | E22: =IF($A22="","",INDEX(Assessment!$G:$G,$A22)) | F22: =IF($A22="","",INDEX(Assessment!$H:$H,$A22)) | G22: =IF($A22="","",INDEX(Assessment!$I:$I,$A22))
A23: =IFERROR(MATCH(19,Assessment!$M:$M,0),"") | B23: =IF($A23="","",INDEX(Assessment!$B:$B,$A23)) | C23: =IF($A23="","",INDEX(Assessment!$D:$D,$A23)) | D23: =IF($A23="","",INDEX(Assessment!$E:$E,$A23)) | E23: =IF($A23="","",INDEX(Assessment!$G:$G,$A23)) | F23: =IF($A23="","",INDEX(Assessment!$H:$H,$A23)) | G23: =IF($A23="","",INDEX(Assessment!$I:$I,$A23))
A24: =IFERROR(MATCH(20,Assessment!$M:$M,0),"") | B24: =IF($A24="","",INDEX(Assessment!$B:$B,$A24)) | C24: =IF($A24="","",INDEX(Assessment!$D:$D,$A24)) | D24: =IF($A24="","",INDEX(Assessment!$E:$E,$A24)) | E24: =IF($A24="","",INDEX(Assessment!$G:$G,$A24)) | F24: =IF($A24="","",INDEX(Assessment!$H:$H,$A24)) | G24: =IF($A24="","",INDEX(Assessment!$I:$I,$A24))
A25: =IFERROR(MATCH(21,Assessment!$M:$M,0),"") | B25: =IF($A25="","",INDEX(Assessment!$B:$B,$A25)) | C25: =IF($A25="","",INDEX(Assessment!$D:$D,$A25)) | D25: =IF($A25="","",INDEX(Assessment!$E:$E,$A25)) | E25: =IF($A25="","",INDEX(Assessment!$G:$G,$A25)) | F25: =IF($A25="","",INDEX(Assessment!$H:$H,$A25)) | G25: =IF($A25="","",INDEX(Assessment!$I:$I,$A25))
A26: =IFERROR(MATCH(22,Assessment!$M:$M,0),"") | B26: =IF($A26="","",INDEX(Assessment!$B:$B,$A26)) | C26: =IF($A26="","",INDEX(Assessment!$D:$D,$A26)) | D26: =IF($A26="","",INDEX(Assessment!$E:$E,$A26)) | E26: =IF($A26="","",INDEX(Assessment!$G:$G,$A26)) | F26: =IF($A26="","",INDEX(Assessment!$H:$H,$A26)) | G26: =IF($A26="","",INDEX(Assessment!$I:$I,$A26))
A27: =IFERROR(MATCH(23,Assessment!$M:$M,0),"") | B27: =IF($A27="","",INDEX(Assessment!$B:$B,$A27)) | C27: =IF($A27="","",INDEX(Assessment!$D:$D,$A27)) | D27: =IF($A27="","",INDEX(Assessment!$E:$E,$A27)) | E27: =IF($A27="","",INDEX(Assessment!$G:$G,$A27)) | F27: =IF($A27="","",INDEX(Assessment!$H:$H,$A27)) | G27: =IF($A27="","",INDEX(Assessment!$I:$I,$A27))
A28: =IFERROR(MATCH(24,Assessment!$M:$M,0),"") | B28: =IF($A28="","",INDEX(Assessment!$B:$B,$A28)) | C28: =IF($A28="","",INDEX(Assessment!$D:$D,$A28)) | D28: =IF($A28="","",INDEX(Assessment!$E:$E,$A28)) | E28: =IF($A28="","",INDEX(Assessment!$G:$G,$A28)) | F28: =IF($A28="","",INDEX(Assessment!$H:$H,$A28)) | G28: =IF($A28="","",INDEX(Assessment!$I:$I,$A28))
A29: =IFERROR(MATCH(25,Assessment!$M:$M,0),"") | B29: =IF($A29="","",INDEX(Assessment!$B:$B,$A29)) | C29: =IF($A29="","",INDEX(Assessment!$D:$D,$A29)) | D29: =IF($A29="","",INDEX(Assessment!$E:$E,$A29)) | E29: =IF($A29="","",INDEX(Assessment!$G:$G,$A29)) | F29: =IF($A29="","",INDEX(Assessment!$H:$H,$A29)) | G29: =IF($A29="","",INDEX(Assessment!$I:$I,$A29))
A30: =IFERROR(MATCH(26,Assessment!$M:$M,0),"") | B30: =IF($A30="","",INDEX(Assessment!$B:$B,$A30)) | C30: =IF($A30="","",INDEX(Assessment!$D:$D,$A30)) | D30: =IF($A30="","",INDEX(Assessment!$E:$E,$A30)) | E30: =IF($A30="","",INDEX(Assessment!$G:$G,$A30)) | F30: =IF($A30="","",INDEX(Assessment!$H:$H,$A30)) | G30: =IF($A30="","",INDEX(Assessment!$I:$I,$A30))
A31: =IFERROR(MATCH(27,Assessment!$M:$M,0),"") | B31: =IF($A31="","",INDEX(Assessment!$B:$B,$A31)) | C31: =IF($A31="","",INDEX(Assessment!$D:$D,$A31)) | D31: =IF($A31="","",INDEX(Assessment!$E:$E,$A31)) | E31: =IF($A31="","",INDEX(Assessment!$G:$G,$A31)) | F31: =IF($A31="","",INDEX(Assessment!$H:$H,$A31)) | G31: =IF($A31="","",INDEX(Assessment!$I:$I,$A31))
A32: =IFERROR(MATCH(28,Assessment!$M:$M,0),"") | B32: =IF($A32="","",INDEX(Assessment!$B:$B,$A32)) | C32: =IF($A32="","",INDEX(Assessment!$D:$D,$A32)) | D32: =IF($A32="","",INDEX(Assessment!$E:$E,$A32)) | E32: =IF($A32="","",INDEX(Assessment!$G:$G,$A32)) | F32: =IF($A32="","",INDEX(Assessment!$H:$H,$A32)) | G32: =IF($A32="","",INDEX(Assessment!$I:$I,$A32))
A33: =IFERROR(MATCH(29,Assessment!$M:$M,0),"") | B33: =IF($A33="","",INDEX(Assessment!$B:$B,$A33)) | C33: =IF($A33="","",INDEX(Assessment!$D:$D,$A33)) | D33: =IF($A33="","",INDEX(Assessment!$E:$E,$A33)) | E33: =IF($A33="","",INDEX(Assessment!$G:$G,$A33)) | F33: =IF($A33="","",INDEX(Assessment!$H:$H,$A33)) | G33: =IF($A33="","",INDEX(Assessment!$I:$I,$A33))
A34: =IFERROR(MATCH(30,Assessment!$M:$M,0),"") | B34: =IF($A34="","",INDEX(Assessment!$B:$B,$A34)) | C34: =IF($A34="","",INDEX(Assessment!$D:$D,$A34)) | D34: =IF($A34="","",INDEX(Assessment!$E:$E,$A34)) | E34: =IF($A34="","",INDEX(Assessment!$G:$G,$A34)) | F34: =IF($A34="","",INDEX(Assessment!$H:$H,$A34)) | G34: =IF($A34="","",INDEX(Assessment!$I:$I,$A34))
A35: =IFERROR(MATCH(31,Assessment!$M:$M,0),"") | B35: =IF($A35="","",INDEX(Assessment!$B:$B,$A35)) | C35: =IF($A35="","",INDEX(Assessment!$D:$D,$A35)) | D35: =IF($A35="","",INDEX(Assessment!$E:$E,$A35)) | E35: =IF($A35="","",INDEX(Assessment!$G:$G,$A35)) | F35: =IF($A35="","",INDEX(Assessment!$H:$H,$A35)) | G35: =IF($A35="","",INDEX(Assessment!$I:$I,$A35))
A36: =IFERROR(MATCH(32,Assessment!$M:$M,0),"") | B36: =IF($A36="","",INDEX(Assessment!$B:$B,$A36)) | C36: =IF($A36="","",INDEX(Assessment!$D:$D,$A36)) | D36: =IF($A36="","",INDEX(Assessment!$E:$E,$A36)) | E36: =IF($A36="","",INDEX(Assessment!$G:$G,$A36)) | F36: =IF($A36="","",INDEX(Assessment!$H:$H,$A36)) | G36: =IF($A36="","",INDEX(Assessment!$I:$I,$A36))
A37: =IFERROR(MATCH(33,Assessment!$M:$M,0),"") | B37: =IF($A37="","",INDEX(Assessment!$B:$B,$A37)) | C37: =IF($A37="","",INDEX(Assessment!$D:$D,$A37)) | D37: =IF($A37="","",INDEX(Assessment!$E:$E,$A37)) | E37: =IF($A37="","",INDEX(Assessment!$G:$G,$A37)) | F37: =IF($A37="","",INDEX(Assessment!$H:$H,$A37)) | G37: =IF($A37="","",INDEX(Assessment!$I:$I,$A37))
A38: =IFERROR(MATCH(34,Assessment!$M:$M,0),"") | B38: =IF($A38="","",INDEX(Assessment!$B:$B,$A38)) | C38: =IF($A38="","",INDEX(Assessment!$D:$D,$A38)) | D38: =IF($A38="","",INDEX(Assessment!$E:$E,$A38)) | E38: =IF($A38="","",INDEX(Assessment!$G:$G,$A38)) | F38: =IF($A38="","",INDEX(Assessment!$H:$H,$A38)) | G38: =IF($A38="","",INDEX(Assessment!$I:$I,$A38))
A39: =IFERROR(MATCH(35,Assessment!$M:$M,0),"") | B39: =IF($A39="","",INDEX(Assessment!$B:$B,$A39)) | C39: =IF($A39="","",INDEX(Assessment!$D:$D,$A39)) | D39: =IF($A39="","",INDEX(Assessment!$E:$E,$A39)) | E39: =IF($A39="","",INDEX(Assessment!$G:$G,$A39)) | F39: =IF($A39="","",INDEX(Assessment!$H:$H,$A39)) | G39: =IF($A39="","",INDEX(Assessment!$I:$I,$A39))
A40: =IFERROR(MATCH(36,Assessment!$M:$M,0),"") | B40: =IF($A40="","",INDEX(Assessment!$B:$B,$A40)) | C40: =IF($A40="","",INDEX(Assessment!$D:$D,$A40)) | D40: =IF($A40="","",INDEX(Assessment!$E:$E,$A40)) | E40: =IF($A40="","",INDEX(Assessment!$G:$G,$A40)) | F40: =IF($A40="","",INDEX(Assessment!$H:$H,$A40)) | G40: =IF($A40="","",INDEX(Assessment!$I:$I,$A40))
A41: =IFERROR(MATCH(37,Assessment!$M:$M,0),"") | B41: =IF($A41="","",INDEX(Assessment!$B:$B,$A41)) | C41: =IF($A41="","",INDEX(Assessment!$D:$D,$A41)) | D41: =IF($A41="","",INDEX(Assessment!$E:$E,$A41)) | E41: =IF($A41="","",INDEX(Assessment!$G:$G,$A41)) | F41: =IF($A41="","",INDEX(Assessment!$H:$H,$A41)) | G41: =IF($A41="","",INDEX(Assessment!$I:$I,$A41))
...

Sheet Product Backlog (FB)
A1: PRODUCT BACKLOG (FB)
A3: Feature Gap items — TownSq genuinely cannot support these today. Column 'TownSq today' shows the current constraint. Assign P0–P3 priority. These drive the TownSq product roadmap.
A4: Row# | B4: Priority (P0–P3) | C4: Domain | D4: Capability | E4: Dimension | F4: Discovery Question | G4: Branch Answer (evidence) | H4: TownSq today (why it's a gap) | I4: Gap Description | J4: Effort Estimate | K4: Status
A5: =IFERROR(MATCH(1,Assessment!$N:$N,0),"") | B5: =IF($A5="","",INDEX(Assessment!$K:$K,$A5)) | C5: =IF($A5="","",INDEX(Assessment!$B:$B,$A5)) | D5: =IF($A5="","",INDEX(Assessment!$D:$D,$A5)) | E5: =IF($A5="","",INDEX(Assessment!$E:$E,$A5)) | F5: =IF($A5="","",INDEX(Assessment!$G:$G,$A5)) | G5: =IF($A5="","",INDEX(Assessment!$H:$H,$A5)) | H5: =IF($A5="","",INDEX(Assessment!$I:$I,$A5))
A6: =IFERROR(MATCH(2,Assessment!$N:$N,0),"") | B6: =IF($A6="","",INDEX(Assessment!$K:$K,$A6)) | C6: =IF($A6="","",INDEX(Assessment!$B:$B,$A6)) | D6: =IF($A6="","",INDEX(Assessment!$D:$D,$A6)) | E6: =IF($A6="","",INDEX(Assessment!$E:$E,$A6)) | F6: =IF($A6="","",INDEX(Assessment!$G:$G,$A6)) | G6: =IF($A6="","",INDEX(Assessment!$H:$H,$A6)) | H6: =IF($A6="","",INDEX(Assessment!$I:$I,$A6))
A7: =IFERROR(MATCH(3,Assessment!$N:$N,0),"") | B7: =IF($A7="","",INDEX(Assessment!$K:$K,$A7)) | C7: =IF($A7="","",INDEX(Assessment!$B:$B,$A7)) | D7: =IF($A7="","",INDEX(Assessment!$D:$D,$A7)) | E7: =IF($A7="","",INDEX(Assessment!$E:$E,$A7)) | F7: =IF($A7="","",INDEX(Assessment!$G:$G,$A7)) | G7: =IF($A7="","",INDEX(Assessment!$H:$H,$A7)) | H7: =IF($A7="","",INDEX(Assessment!$I:$I,$A7))
A8: =IFERROR(MATCH(4,Assessment!$N:$N,0),"") | B8: =IF($A8="","",INDEX(Assessment!$K:$K,$A8)) | C8: =IF($A8="","",INDEX(Assessment!$B:$B,$A8)) | D8: =IF($A8="","",INDEX(Assessment!$D:$D,$A8)) | E8: =IF($A8="","",INDEX(Assessment!$E:$E,$A8)) | F8: =IF($A8="","",INDEX(Assessment!$G:$G,$A8)) | G8: =IF($A8="","",INDEX(Assessment!$H:$H,$A8)) | H8: =IF($A8="","",INDEX(Assessment!$I:$I,$A8))
A9: =IFERROR(MATCH(5,Assessment!$N:$N,0),"") | B9: =IF($A9="","",INDEX(Assessment!$K:$K,$A9)) | C9: =IF($A9="","",INDEX(Assessment!$B:$B,$A9)) | D9: =IF($A9="","",INDEX(Assessment!$D:$D,$A9)) | E9: =IF($A9="","",INDEX(Assessment!$E:$E,$A9)) | F9: =IF($A9="","",INDEX(Assessment!$G:$G,$A9)) | G9: =IF($A9="","",INDEX(Assessment!$H:$H,$A9)) | H9: =IF($A9="","",INDEX(Assessment!$I:$I,$A9))
A10: =IFERROR(MATCH(6,Assessment!$N:$N,0),"") | B10: =IF($A10="","",INDEX(Assessment!$K:$K,$A10)) | C10: =IF($A10="","",INDEX(Assessment!$B:$B,$A10)) | D10: =IF($A10="","",INDEX(Assessment!$D:$D,$A10)) | E10: =IF($A10="","",INDEX(Assessment!$E:$E,$A10)) | F10: =IF($A10="","",INDEX(Assessment!$G:$G,$A10)) | G10: =IF($A10="","",INDEX(Assessment!$H:$H,$A10)) | H10: =IF($A10="","",INDEX(Assessment!$I:$I,$A10))
A11: =IFERROR(MATCH(7,Assessment!$N:$N,0),"") | B11: =IF($A11="","",INDEX(Assessment!$K:$K,$A11)) | C11: =IF($A11="","",INDEX(Assessment!$B:$B,$A11)) | D11: =IF($A11="","",INDEX(Assessment!$D:$D,$A11)) | E11: =IF($A11="","",INDEX(Assessment!$E:$E,$A11)) | F11: =IF($A11="","",INDEX(Assessment!$G:$G,$A11)) | G11: =IF($A11="","",INDEX(Assessment!$H:$H,$A11)) | H11: =IF($A11="","",INDEX(Assessment!$I:$I,$A11))
A12: =IFERROR(MATCH(8,Assessment!$N:$N,0),"") | B12: =IF($A12="","",INDEX(Assessment!$K:$K,$A12)) | C12: =IF($A12="","",INDEX(Assessment!$B:$B,$A12)) | D12: =IF($A12="","",INDEX(Assessment!$D:$D,$A12)) | E12: =IF($A12="","",INDEX(Assessment!$E:$E,$A12)) | F12: =IF($A12="","",INDEX(Assessment!$G:$G,$A12)) | G12: =IF($A12="","",INDEX(Assessment!$H:$H,$A12)) | H12: =IF($A12="","",INDEX(Assessment!$I:$I,$A12))
A13: =IFERROR(MATCH(9,Assessment!$N:$N,0),"") | B13: =IF($A13="","",INDEX(Assessment!$K:$K,$A13)) | C13: =IF($A13="","",INDEX(Assessment!$B:$B,$A13)) | D13: =IF($A13="","",INDEX(Assessment!$D:$D,$A13)) | E13: =IF($A13="","",INDEX(Assessment!$E:$E,$A13)) | F13: =IF($A13="","",INDEX(Assessment!$G:$G,$A13)) | G13: =IF($A13="","",INDEX(Assessment!$H:$H,$A13)) | H13: =IF($A13="","",INDEX(Assessment!$I:$I,$A13))
A14: =IFERROR(MATCH(10,Assessment!$N:$N,0),"") | B14: =IF($A14="","",INDEX(Assessment!$K:$K,$A14)) | C14: =IF($A14="","",INDEX(Assessment!$B:$B,$A14)) | D14: =IF($A14="","",INDEX(Assessment!$D:$D,$A14)) | E14: =IF($A14="","",INDEX(Assessment!$E:$E,$A14)) | F14: =IF($A14="","",INDEX(Assessment!$G:$G,$A14)) | G14: =IF($A14="","",INDEX(Assessment!$H:$H,$A14)) | H14: =IF($A14="","",INDEX(Assessment!$I:$I,$A14))
A15: =IFERROR(MATCH(11,Assessment!$N:$N,0),"") | B15: =IF($A15="","",INDEX(Assessment!$K:$K,$A15)) | C15: =IF($A15="","",INDEX(Assessment!$B:$B,$A15)) | D15: =IF($A15="","",INDEX(Assessment!$D:$D,$A15)) | E15: =IF($A15="","",INDEX(Assessment!$E:$E,$A15)) | F15: =IF($A15="","",INDEX(Assessment!$G:$G,$A15)) | G15: =IF($A15="","",INDEX(Assessment!$H:$H,$A15)) | H15: =IF($A15="","",INDEX(Assessment!$I:$I,$A15))
A16: =IFERROR(MATCH(12,Assessment!$N:$N,0),"") | B16: =IF($A16="","",INDEX(Assessment!$K:$K,$A16)) | C16: =IF($A16="","",INDEX(Assessment!$B:$B,$A16)) | D16: =IF($A16="","",INDEX(Assessment!$D:$D,$A16)) | E16: =IF($A16="","",INDEX(Assessment!$E:$E,$A16)) | F16: =IF($A16="","",INDEX(Assessment!$G:$G,$A16)) | G16: =IF($A16="","",INDEX(Assessment!$H:$H,$A16)) | H16: =IF($A16="","",INDEX(Assessment!$I:$I,$A16))
A17: =IFERROR(MATCH(13,Assessment!$N:$N,0),"") | B17: =IF($A17="","",INDEX(Assessment!$K:$K,$A17)) | C17: =IF($A17="","",INDEX(Assessment!$B:$B,$A17)) | D17: =IF($A17="","",INDEX(Assessment!$D:$D,$A17)) | E17: =IF($A17="","",INDEX(Assessment!$E:$E,$A17)) | F17: =IF($A17="","",INDEX(Assessment!$G:$G,$A17)) | G17: =IF($A17="","",INDEX(Assessment!$H:$H,$A17)) | H17: =IF($A17="","",INDEX(Assessment!$I:$I,$A17))
A18: =IFERROR(MATCH(14,Assessment!$N:$N,0),"") | B18: =IF($A18="","",INDEX(Assessment!$K:$K,$A18)) | C18: =IF($A18="","",INDEX(Assessment!$B:$B,$A18)) | D18: =IF($A18="","",INDEX(Assessment!$D:$D,$A18)) | E18: =IF($A18="","",INDEX(Assessment!$E:$E,$A18)) | F18: =IF($A18="","",INDEX(Assessment!$G:$G,$A18)) | G18: =IF($A18="","",INDEX(Assessment!$H:$H,$A18)) | H18: =IF($A18="","",INDEX(Assessment!$I:$I,$A18))
A19: =IFERROR(MATCH(15,Assessment!$N:$N,0),"") | B19: =IF($A19="","",INDEX(Assessment!$K:$K,$A19)) | C19: =IF($A19="","",INDEX(Assessment!$B:$B,$A19)) | D19: =IF($A19="","",INDEX(Assessment!$D:$D,$A19)) | E19: =IF($A19="","",INDEX(Assessment!$E:$E,$A19)) | F19: =IF($A19="","",INDEX(Assessment!$G:$G,$A19)) | G19: =IF($A19="","",INDEX(Assessment!$H:$H,$A19)) | H19: =IF($A19="","",INDEX(Assessment!$I:$I,$A19))
A20: =IFERROR(MATCH(16,Assessment!$N:$N,0),"") | B20: =IF($A20="","",INDEX(Assessment!$K:$K,$A20)) | C20: =IF($A20="","",INDEX(Assessment!$B:$B,$A20)) | D20: =IF($A20="","",INDEX(Assessment!$D:$D,$A20)) | E20: =IF($A20="","",INDEX(Assessment!$E:$E,$A20)) | F20: =IF($A20="","",INDEX(Assessment!$G:$G,$A20)) | G20: =IF($A20="","",INDEX(Assessment!$H:$H,$A20)) | H20: =IF($A20="","",INDEX(Assessment!$I:$I,$A20))
A21: =IFERROR(MATCH(17,Assessment!$N:$N,0),"") | B21: =IF($A21="","",INDEX(Assessment!$K:$K,$A21)) | C21: =IF($A21="","",INDEX(Assessment!$B:$B,$A21)) | D21: =IF($A21="","",INDEX(Assessment!$D:$D,$A21)) | E21: =IF($A21="","",INDEX(Assessment!$E:$E,$A21)) | F21: =IF($A21="","",INDEX(Assessment!$G:$G,$A21)) | G21: =IF($A21="","",INDEX(Assessment!$H:$H,$A21)) | H21: =IF($A21="","",INDEX(Assessment!$I:$I,$A21))
A22: =IFERROR(MATCH(18,Assessment!$N:$N,0),"") | B22: =IF($A22="","",INDEX(Assessment!$K:$K,$A22)) | C22: =IF($A22="","",INDEX(Assessment!$B:$B,$A22)) | D22: =IF($A22="","",INDEX(Assessment!$D:$D,$A22)) | E22: =IF($A22="","",INDEX(Assessment!$E:$E,$A22)) | F22: =IF($A22="","",INDEX(Assessment!$G:$G,$A22)) | G22: =IF($A22="","",INDEX(Assessment!$H:$H,$A22)) | H22: =IF($A22="","",INDEX(Assessment!$I:$I,$A22))
A23: =IFERROR(MATCH(19,Assessment!$N:$N,0),"") | B23: =IF($A23="","",INDEX(Assessment!$K:$K,$A23)) | C23: =IF($A23="","",INDEX(Assessment!$B:$B,$A23)) | D23: =IF($A23="","",INDEX(Assessment!$D:$D,$A23)) | E23: =IF($A23="","",INDEX(Assessment!$E:$E,$A23)) | F23: =IF($A23="","",INDEX(Assessment!$G:$G,$A23)) | G23: =IF($A23="","",INDEX(Assessment!$H:$H,$A23)) | H23: =IF($A23="","",INDEX(Assessment!$I:$I,$A23))
A24: =IFERROR(MATCH(20,Assessment!$N:$N,0),"") | B24: =IF($A24="","",INDEX(Assessment!$K:$K,$A24)) | C24: =IF($A24="","",INDEX(Assessment!$B:$B,$A24)) | D24: =IF($A24="","",INDEX(Assessment!$D:$D,$A24)) | E24: =IF($A24="","",INDEX(Assessment!$E:$E,$A24)) | F24: =IF($A24="","",INDEX(Assessment!$G:$G,$A24)) | G24: =IF($A24="","",INDEX(Assessment!$H:$H,$A24)) | H24: =IF($A24="","",INDEX(Assessment!$I:$I,$A24))
A25: =IFERROR(MATCH(21,Assessment!$N:$N,0),"") | B25: =IF($A25="","",INDEX(Assessment!$K:$K,$A25)) | C25: =IF($A25="","",INDEX(Assessment!$B:$B,$A25)) | D25: =IF($A25="","",INDEX(Assessment!$D:$D,$A25)) | E25: =IF($A25="","",INDEX(Assessment!$E:$E,$A25)) | F25: =IF($A25="","",INDEX(Assessment!$G:$G,$A25)) | G25: =IF($A25="","",INDEX(Assessment!$H:$H,$A25)) | H25: =IF($A25="","",INDEX(Assessment!$I:$I,$A25))
A26: =IFERROR(MATCH(22,Assessment!$N:$N,0),"") | B26: =IF($A26="","",INDEX(Assessment!$K:$K,$A26)) | C26: =IF($A26="","",INDEX(Assessment!$B:$B,$A26)) | D26: =IF($A26="","",INDEX(Assessment!$D:$D,$A26)) | E26: =IF($A26="","",INDEX(Assessment!$E:$E,$A26)) | F26: =IF($A26="","",INDEX(Assessment!$G:$G,$A26)) | G26: =IF($A26="","",INDEX(Assessment!$H:$H,$A26)) | H26: =IF($A26="","",INDEX(Assessment!$I:$I,$A26))
A27: =IFERROR(MATCH(23,Assessment!$N:$N,0),"") | B27: =IF($A27="","",INDEX(Assessment!$K:$K,$A27)) | C27: =IF($A27="","",INDEX(Assessment!$B:$B,$A27)) | D27: =IF($A27="","",INDEX(Assessment!$D:$D,$A27)) | E27: =IF($A27="","",INDEX(Assessment!$E:$E,$A27)) | F27: =IF($A27="","",INDEX(Assessment!$G:$G,$A27)) | G27: =IF($A27="","",INDEX(Assessment!$H:$H,$A27)) | H27: =IF($A27="","",INDEX(Assessment!$I:$I,$A27))
A28: =IFERROR(MATCH(24,Assessment!$N:$N,0),"") | B28: =IF($A28="","",INDEX(Assessment!$K:$K,$A28)) | C28: =IF($A28="","",INDEX(Assessment!$B:$B,$A28)) | D28: =IF($A28="","",INDEX(Assessment!$D:$D,$A28)) | E28: =IF($A28="","",INDEX(Assessment!$E:$E,$A28)) | F28: =IF($A28="","",INDEX(Assessment!$G:$G,$A28)) | G28: =IF($A28="","",INDEX(Assessment!$H:$H,$A28)) | H28: =IF($A28="","",INDEX(Assessment!$I:$I,$A28))
A29: =IFERROR(MATCH(25,Assessment!$N:$N,0),"") | B29: =IF($A29="","",INDEX(Assessment!$K:$K,$A29)) | C29: =IF($A29="","",INDEX(Assessment!$B:$B,$A29)) | D29: =IF($A29="","",INDEX(Assessment!$D:$D,$A29)) | E29: =IF($A29="","",INDEX(Assessment!$E:$E,$A29)) | F29: =IF($A29="","",INDEX(Assessment!$G:$G,$A29)) | G29: =IF($A29="","",INDEX(Assessment!$H:$H,$A29)) | H29: =IF($A29="","",INDEX(Assessment!$I:$I,$A29))
A30: =IFERROR(MATCH(26,Assessment!$N:$N,0),"") | B30: =IF($A30="","",INDEX(Assessment!$K:$K,$A30)) | C30: =IF($A30="","",INDEX(Assessment!$B:$B,$A30)) | D30: =IF($A30="","",INDEX(Assessment!$D:$D,$A30)) | E30: =IF($A30="","",INDEX(Assessment!$E:$E,$A30)) | F30: =IF($A30="","",INDEX(Assessment!$G:$G,$A30)) | G30: =IF($A30="","",INDEX(Assessment!$H:$H,$A30)) | H30: =IF($A30="","",INDEX(Assessment!$I:$I,$A30))
A31: =IFERROR(MATCH(27,Assessment!$N:$N,0),"") | B31: =IF($A31="","",INDEX(Assessment!$K:$K,$A31)) | C31: =IF($A31="","",INDEX(Assessment!$B:$B,$A31)) | D31: =IF($A31="","",INDEX(Assessment!$D:$D,$A31)) | E31: =IF($A31="","",INDEX(Assessment!$E:$E,$A31)) | F31: =IF($A31="","",INDEX(Assessment!$G:$G,$A31)) | G31: =IF($A31="","",INDEX(Assessment!$H:$H,$A31)) | H31: =IF($A31="","",INDEX(Assessment!$I:$I,$A31))
